  0%|                                                           | 0/17 [00:34<?, ?it/s]
Traceback (most recent call last):
  File "C:\Users\prana\Documents\Python_Stuff\Ariel-Data-Challenge-2024\main.py", line 65, in <module>
    train_valid_test(model = CNN(), train_loader = train_loader, valid_loader = valid_loader, loss_func = loss_func)
  File "C:\Users\prana\Documents\Python_Stuff\Ariel-Data-Challenge-2024\trainer.py", line 64, in __init__
    self.__train_init()
  File "C:\Users\prana\Documents\Python_Stuff\Ariel-Data-Challenge-2024\trainer.py", line 75, in __train_init
    running_loss = self.__train_core()
                   ^^^^^^^^^^^^^^^^^^^
  File "C:\Users\prana\Documents\Python_Stuff\Ariel-Data-Challenge-2024\trainer.py", line 119, in __train_core
    loss = self.__run_batch(inps, label)
           ^^^^^^^^^^^^^^^^^^^^^^^^^^^^^
  File "C:\Users\prana\Documents\Python_Stuff\Ariel-Data-Challenge-2024\trainer.py", line 129, in __run_batch
    inps["signals"]["FGS1"] = inps["signals"]["FGS1"].to(self.device)
                              ~~~~^^^^^^^^^^^
KeyError: 'signals'
